Traceback (most recent call last):
  File "/home/babugasl/src/passenger_wsgi.py", line 6, in <module>
    from ssp.wsgi import application 
  File "/home/babugasl/src/ssp/wsgi.py", line 16, in <module>
    application = get_wsgi_application()
  File "/home/babugasl/virtualenv/src/3.8/lib/python3.8/site-packages/django/core/wsgi.py", line 12, in get_wsgi_application
    django.setup(set_prefix=False)
  File "/home/babugasl/virtualenv/src/3.8/lib/python3.8/site-packages/django/__init__.py", line 24, in setup
    apps.populate(settings.INSTALLED_APPS)
  File "/home/babugasl/virtualenv/src/3.8/lib/python3.8/site-packages/django/apps/registry.py", line 124, in populate
    app_config.ready()
  File "/home/babugasl/src/user_account/apps.py", line 9, in ready
    import user_account.signals
  File "/home/babugasl/src/user_account/signals.py", line 24
    print("message sent")
    ^
SyntaxError: invalid syntax
Traceback (most recent call last):
  File "/home/babugasl/src/passenger_wsgi.py", line 6, in <module>
    from ssp.wsgi import application 
  File "/home/babugasl/src/ssp/wsgi.py", line 16, in <module>
    application = get_wsgi_application()
  File "/home/babugasl/virtualenv/src/3.8/lib/python3.8/site-packages/django/core/wsgi.py", line 12, in get_wsgi_application
    django.setup(set_prefix=False)
  File "/home/babugasl/virtualenv/src/3.8/lib/python3.8/site-packages/django/__init__.py", line 24, in setup
    apps.populate(settings.INSTALLED_APPS)
  File "/home/babugasl/virtualenv/src/3.8/lib/python3.8/site-packages/django/apps/registry.py", line 83, in populate
    raise RuntimeError("populate() isn't reentrant")
RuntimeError: populate() isn't reentrant
[UID:4101][15962] Child process with pid: 16001 was killed by signal: 15, core dump: 0
Traceback (most recent call last):
  File "/home/babugasl/src/passenger_wsgi.py", line 6, in <module>
    from ssp.wsgi import application 
  File "/home/babugasl/src/ssp/wsgi.py", line 16, in <module>
    application = get_wsgi_application()
  File "/home/babugasl/virtualenv/src/3.8/lib/python3.8/site-packages/django/core/wsgi.py", line 12, in get_wsgi_application
    django.setup(set_prefix=False)
  File "/home/babugasl/virtualenv/src/3.8/lib/python3.8/site-packages/django/__init__.py", line 24, in setup
    apps.populate(settings.INSTALLED_APPS)
  File "/home/babugasl/virtualenv/src/3.8/lib/python3.8/site-packages/django/apps/registry.py", line 83, in populate
    raise RuntimeError("populate() isn't reentrant")
RuntimeError: populate() isn't reentrant
[UID:4101][15962] Child process with pid: 16167 was killed by signal: 15, core dump: 0
Traceback (most recent call last):
  File "/home/babugasl/src/passenger_wsgi.py", line 6, in <module>
    from ssp.wsgi import application 
  File "/home/babugasl/src/ssp/wsgi.py", line 16, in <module>
    application = get_wsgi_application()
  File "/home/babugasl/virtualenv/src/3.8/lib/python3.8/site-packages/django/core/wsgi.py", line 12, in get_wsgi_application
    django.setup(set_prefix=False)
  File "/home/babugasl/virtualenv/src/3.8/lib/python3.8/site-packages/django/__init__.py", line 24, in setup
    apps.populate(settings.INSTALLED_APPS)
  File "/home/babugasl/virtualenv/src/3.8/lib/python3.8/site-packages/django/apps/registry.py", line 83, in populate
    raise RuntimeError("populate() isn't reentrant")
RuntimeError: populate() isn't reentrant
[UID:4101][15962] Child process with pid: 22282 was killed by signal: 15, core dump: 0
Traceback (most recent call last):
  File "/home/babugasl/src/passenger_wsgi.py", line 6, in <module>
    from ssp.wsgi import application 
  File "/home/babugasl/src/ssp/wsgi.py", line 16, in <module>
    application = get_wsgi_application()
  File "/home/babugasl/virtualenv/src/3.8/lib/python3.8/site-packages/django/core/wsgi.py", line 12, in get_wsgi_application
    django.setup(set_prefix=False)
  File "/home/babugasl/virtualenv/src/3.8/lib/python3.8/site-packages/django/__init__.py", line 24, in setup
    apps.populate(settings.INSTALLED_APPS)
  File "/home/babugasl/virtualenv/src/3.8/lib/python3.8/site-packages/django/apps/registry.py", line 83, in populate
    raise RuntimeError("populate() isn't reentrant")
RuntimeError: populate() isn't reentrant
[UID:4101][15962] Child process with pid: 30942 was killed by signal: 15, core dump: 0
Traceback (most recent call last):
  File "/home/babugasl/src/passenger_wsgi.py", line 6, in <module>
    from ssp.wsgi import application 
  File "/home/babugasl/src/ssp/wsgi.py", line 16, in <module>
    application = get_wsgi_application()
  File "/home/babugasl/virtualenv/src/3.8/lib/python3.8/site-packages/django/core/wsgi.py", line 12, in get_wsgi_application
    django.setup(set_prefix=False)
  File "/home/babugasl/virtualenv/src/3.8/lib/python3.8/site-packages/django/__init__.py", line 24, in setup
    apps.populate(settings.INSTALLED_APPS)
  File "/home/babugasl/virtualenv/src/3.8/lib/python3.8/site-packages/django/apps/registry.py", line 83, in populate
    raise RuntimeError("populate() isn't reentrant")
RuntimeError: populate() isn't reentrant
[UID:4101][15962] Child process with pid: 415 was killed by signal: 15, core dump: 0
Traceback (most recent call last):
  File "/home/babugasl/src/passenger_wsgi.py", line 6, in <module>
    from ssp.wsgi import application 
  File "/home/babugasl/src/ssp/wsgi.py", line 16, in <module>
    application = get_wsgi_application()
  File "/home/babugasl/virtualenv/src/3.8/lib/python3.8/site-packages/django/core/wsgi.py", line 12, in get_wsgi_application
    django.setup(set_prefix=False)
  File "/home/babugasl/virtualenv/src/3.8/lib/python3.8/site-packages/django/__init__.py", line 24, in setup
    apps.populate(settings.INSTALLED_APPS)
  File "/home/babugasl/virtualenv/src/3.8/lib/python3.8/site-packages/django/apps/registry.py", line 124, in populate
    app_config.ready()
  File "/home/babugasl/src/user_account/apps.py", line 9, in ready
    import user_account.signals
  File "/home/babugasl/src/user_account/signals.py", line 24
    print("message sent")
    ^
SyntaxError: invalid syntax
Traceback (most recent call last):
  File "/home/babugasl/src/passenger_wsgi.py", line 6, in <module>
    from ssp.wsgi import application 
  File "/home/babugasl/src/ssp/wsgi.py", line 16, in <module>
    application = get_wsgi_application()
  File "/home/babugasl/virtualenv/src/3.8/lib/python3.8/site-packages/django/core/wsgi.py", line 12, in get_wsgi_application
    django.setup(set_prefix=False)
  File "/home/babugasl/virtualenv/src/3.8/lib/python3.8/site-packages/django/__init__.py", line 24, in setup
    apps.populate(settings.INSTALLED_APPS)
  File "/home/babugasl/virtualenv/src/3.8/lib/python3.8/site-packages/django/apps/registry.py", line 83, in populate
    raise RuntimeError("populate() isn't reentrant")
RuntimeError: populate() isn't reentrant
[UID:4101][19887] Child process with pid: 19919 was killed by signal: 15, core dump: 0
Internal Server Error: /courses/1/flag-issue
Traceback (most recent call last):
  File "/home/babugasl/virtualenv/src/3.8/lib/python3.8/site-packages/django/core/handlers/exception.py", line 55, in inner
    response = get_response(request)
  File "/home/babugasl/virtualenv/src/3.8/lib/python3.8/site-packages/django/core/handlers/base.py", line 197, in _get_response
    response = wrapped_callback(request, *callback_args, **callback_kwargs)
  File "/home/babugasl/src/app/views.py", line 143, in flag_course
    issue.save()
  File "/home/babugasl/virtualenv/src/3.8/lib/python3.8/site-packages/django/db/models/base.py", line 814, in save
    self.save_base(
  File "/home/babugasl/virtualenv/src/3.8/lib/python3.8/site-packages/django/db/models/base.py", line 892, in save_base
    post_save.send(
  File "/home/babugasl/virtualenv/src/3.8/lib/python3.8/site-packages/django/dispatch/dispatcher.py", line 176, in send
    return [
  File "/home/babugasl/virtualenv/src/3.8/lib/python3.8/site-packages/django/dispatch/dispatcher.py", line 177, in <listcomp>
    (receiver, receiver(signal=self, sender=sender, **named))
  File "/home/babugasl/src/user_account/signals.py", line 23, in send_issue_email
    send_mail(subject, message, from_email, recipient_list)
  File "/home/babugasl/virtualenv/src/3.8/lib/python3.8/site-packages/django/core/mail/__init__.py", line 87, in send_mail
    return mail.send()
  File "/home/babugasl/virtualenv/src/3.8/lib/python3.8/site-packages/django/core/mail/message.py", line 298, in send
    return self.get_connection(fail_silently).send_messages([self])
  File "/home/babugasl/virtualenv/src/3.8/lib/python3.8/site-packages/django/core/mail/backends/smtp.py", line 127, in send_messages
    new_conn_created = self.open()
  File "/home/babugasl/virtualenv/src/3.8/lib/python3.8/site-packages/django/core/mail/backends/smtp.py", line 85, in open
    self.connection = self.connection_class(
  File "/opt/alt/python38/lib64/python3.8/smtplib.py", line 255, in __init__
    (code, msg) = self.connect(host, port)
  File "/opt/alt/python38/lib64/python3.8/smtplib.py", line 339, in connect
    self.sock = self._get_socket(host, port, self.timeout)
  File "/opt/alt/python38/lib64/python3.8/smtplib.py", line 310, in _get_socket
    return socket.create_connection((host, port), timeout,
  File "/opt/alt/python38/lib64/python3.8/socket.py", line 787, in create_connection
    for res in getaddrinfo(host, port, 0, SOCK_STREAM):
  File "/opt/alt/python38/lib64/python3.8/socket.py", line 918, in getaddrinfo
    for res in _socket.getaddrinfo(host, port, family, type, proto, flags):
socket.gaierror: [Errno -2] Name or service not known
Not Found: /static/imgs/text.png
Internal Server Error: /materials/7/flag-issue
Traceback (most recent call last):
  File "/home/babugasl/virtualenv/src/3.8/lib/python3.8/site-packages/django/core/handlers/exception.py", line 55, in inner
    response = get_response(request)
  File "/home/babugasl/virtualenv/src/3.8/lib/python3.8/site-packages/django/core/handlers/base.py", line 197, in _get_response
    response = wrapped_callback(request, *callback_args, **callback_kwargs)
  File "/home/babugasl/src/app/views.py", line 156, in flag_material
    issue.save()
  File "/home/babugasl/virtualenv/src/3.8/lib/python3.8/site-packages/django/db/models/base.py", line 814, in save
    self.save_base(
  File "/home/babugasl/virtualenv/src/3.8/lib/python3.8/site-packages/django/db/models/base.py", line 892, in save_base
    post_save.send(
  File "/home/babugasl/virtualenv/src/3.8/lib/python3.8/site-packages/django/dispatch/dispatcher.py", line 176, in send
    return [
  File "/home/babugasl/virtualenv/src/3.8/lib/python3.8/site-packages/django/dispatch/dispatcher.py", line 177, in <listcomp>
    (receiver, receiver(signal=self, sender=sender, **named))
  File "/home/babugasl/src/user_account/signals.py", line 23, in send_issue_email
    send_mail(subject, message, from_email, recipient_list)
  File "/home/babugasl/virtualenv/src/3.8/lib/python3.8/site-packages/django/core/mail/__init__.py", line 87, in send_mail
    return mail.send()
  File "/home/babugasl/virtualenv/src/3.8/lib/python3.8/site-packages/django/core/mail/message.py", line 298, in send
    return self.get_connection(fail_silently).send_messages([self])
  File "/home/babugasl/virtualenv/src/3.8/lib/python3.8/site-packages/django/core/mail/backends/smtp.py", line 127, in send_messages
    new_conn_created = self.open()
  File "/home/babugasl/virtualenv/src/3.8/lib/python3.8/site-packages/django/core/mail/backends/smtp.py", line 85, in open
    self.connection = self.connection_class(
  File "/opt/alt/python38/lib64/python3.8/smtplib.py", line 255, in __init__
    (code, msg) = self.connect(host, port)
  File "/opt/alt/python38/lib64/python3.8/smtplib.py", line 339, in connect
    self.sock = self._get_socket(host, port, self.timeout)
  File "/opt/alt/python38/lib64/python3.8/smtplib.py", line 310, in _get_socket
    return socket.create_connection((host, port), timeout,
  File "/opt/alt/python38/lib64/python3.8/socket.py", line 787, in create_connection
    for res in getaddrinfo(host, port, 0, SOCK_STREAM):
  File "/opt/alt/python38/lib64/python3.8/socket.py", line 918, in getaddrinfo
    for res in _socket.getaddrinfo(host, port, family, type, proto, flags):
socket.gaierror: [Errno -2] Name or service not known
Not Found: /favicon.ico
Internal Server Error: /materials/7/flag-issue
Traceback (most recent call last):
  File "/home/babugasl/virtualenv/src/3.8/lib/python3.8/site-packages/django/core/handlers/exception.py", line 55, in inner
    response = get_response(request)
  File "/home/babugasl/virtualenv/src/3.8/lib/python3.8/site-packages/django/core/handlers/base.py", line 197, in _get_response
    response = wrapped_callback(request, *callback_args, **callback_kwargs)
  File "/home/babugasl/src/app/views.py", line 156, in flag_material
    issue.save()
  File "/home/babugasl/virtualenv/src/3.8/lib/python3.8/site-packages/django/db/models/base.py", line 814, in save
    self.save_base(
  File "/home/babugasl/virtualenv/src/3.8/lib/python3.8/site-packages/django/db/models/base.py", line 892, in save_base
    post_save.send(
  File "/home/babugasl/virtualenv/src/3.8/lib/python3.8/site-packages/django/dispatch/dispatcher.py", line 176, in send
    return [
  File "/home/babugasl/virtualenv/src/3.8/lib/python3.8/site-packages/django/dispatch/dispatcher.py", line 177, in <listcomp>
    (receiver, receiver(signal=self, sender=sender, **named))
  File "/home/babugasl/src/user_account/signals.py", line 23, in send_issue_email
    send_mail(subject, message, from_email, recipient_list)
  File "/home/babugasl/virtualenv/src/3.8/lib/python3.8/site-packages/django/core/mail/__init__.py", line 87, in send_mail
    return mail.send()
  File "/home/babugasl/virtualenv/src/3.8/lib/python3.8/site-packages/django/core/mail/message.py", line 298, in send
    return self.get_connection(fail_silently).send_messages([self])
  File "/home/babugasl/virtualenv/src/3.8/lib/python3.8/site-packages/django/core/mail/backends/smtp.py", line 127, in send_messages
    new_conn_created = self.open()
  File "/home/babugasl/virtualenv/src/3.8/lib/python3.8/site-packages/django/core/mail/backends/smtp.py", line 85, in open
    self.connection = self.connection_class(
  File "/opt/alt/python38/lib64/python3.8/smtplib.py", line 255, in __init__
    (code, msg) = self.connect(host, port)
  File "/opt/alt/python38/lib64/python3.8/smtplib.py", line 339, in connect
    self.sock = self._get_socket(host, port, self.timeout)
  File "/opt/alt/python38/lib64/python3.8/smtplib.py", line 310, in _get_socket
    return socket.create_connection((host, port), timeout,
  File "/opt/alt/python38/lib64/python3.8/socket.py", line 787, in create_connection
    for res in getaddrinfo(host, port, 0, SOCK_STREAM):
  File "/opt/alt/python38/lib64/python3.8/socket.py", line 918, in getaddrinfo
    for res in _socket.getaddrinfo(host, port, family, type, proto, flags):
socket.gaierror: [Errno -2] Name or service not known
Internal Server Error: /materials/7/flag-issue
Traceback (most recent call last):
  File "/home/babugasl/virtualenv/src/3.8/lib/python3.8/site-packages/django/core/handlers/exception.py", line 55, in inner
    response = get_response(request)
  File "/home/babugasl/virtualenv/src/3.8/lib/python3.8/site-packages/django/core/handlers/base.py", line 197, in _get_response
    response = wrapped_callback(request, *callback_args, **callback_kwargs)
  File "/home/babugasl/src/app/views.py", line 156, in flag_material
    issue.save()
  File "/home/babugasl/virtualenv/src/3.8/lib/python3.8/site-packages/django/db/models/base.py", line 814, in save
    self.save_base(
  File "/home/babugasl/virtualenv/src/3.8/lib/python3.8/site-packages/django/db/models/base.py", line 892, in save_base
    post_save.send(
  File "/home/babugasl/virtualenv/src/3.8/lib/python3.8/site-packages/django/dispatch/dispatcher.py", line 176, in send
    return [
  File "/home/babugasl/virtualenv/src/3.8/lib/python3.8/site-packages/django/dispatch/dispatcher.py", line 177, in <listcomp>
    (receiver, receiver(signal=self, sender=sender, **named))
  File "/home/babugasl/src/user_account/signals.py", line 23, in send_issue_email
    send_mail(subject, message, from_email, recipient_list)
  File "/home/babugasl/virtualenv/src/3.8/lib/python3.8/site-packages/django/core/mail/__init__.py", line 87, in send_mail
    return mail.send()
  File "/home/babugasl/virtualenv/src/3.8/lib/python3.8/site-packages/django/core/mail/message.py", line 298, in send
    return self.get_connection(fail_silently).send_messages([self])
  File "/home/babugasl/virtualenv/src/3.8/lib/python3.8/site-packages/django/core/mail/backends/smtp.py", line 127, in send_messages
    new_conn_created = self.open()
  File "/home/babugasl/virtualenv/src/3.8/lib/python3.8/site-packages/django/core/mail/backends/smtp.py", line 85, in open
    self.connection = self.connection_class(
  File "/opt/alt/python38/lib64/python3.8/smtplib.py", line 255, in __init__
    (code, msg) = self.connect(host, port)
  File "/opt/alt/python38/lib64/python3.8/smtplib.py", line 339, in connect
    self.sock = self._get_socket(host, port, self.timeout)
  File "/opt/alt/python38/lib64/python3.8/smtplib.py", line 310, in _get_socket
    return socket.create_connection((host, port), timeout,
  File "/opt/alt/python38/lib64/python3.8/socket.py", line 787, in create_connection
    for res in getaddrinfo(host, port, 0, SOCK_STREAM):
  File "/opt/alt/python38/lib64/python3.8/socket.py", line 918, in getaddrinfo
    for res in _socket.getaddrinfo(host, port, family, type, proto, flags):
socket.gaierror: [Errno -2] Name or service not known
Internal Server Error: /materials/7/flag-issue
Traceback (most recent call last):
  File "/home/babugasl/virtualenv/src/3.8/lib/python3.8/site-packages/django/core/handlers/exception.py", line 55, in inner
    response = get_response(request)
  File "/home/babugasl/virtualenv/src/3.8/lib/python3.8/site-packages/django/core/handlers/base.py", line 197, in _get_response
    response = wrapped_callback(request, *callback_args, **callback_kwargs)
  File "/home/babugasl/src/app/views.py", line 156, in flag_material
    issue.save()
  File "/home/babugasl/virtualenv/src/3.8/lib/python3.8/site-packages/django/db/models/base.py", line 814, in save
    self.save_base(
  File "/home/babugasl/virtualenv/src/3.8/lib/python3.8/site-packages/django/db/models/base.py", line 892, in save_base
    post_save.send(
  File "/home/babugasl/virtualenv/src/3.8/lib/python3.8/site-packages/django/dispatch/dispatcher.py", line 176, in send
    return [
  File "/home/babugasl/virtualenv/src/3.8/lib/python3.8/site-packages/django/dispatch/dispatcher.py", line 177, in <listcomp>
    (receiver, receiver(signal=self, sender=sender, **named))
  File "/home/babugasl/src/user_account/signals.py", line 23, in send_issue_email
    send_mail(subject, message, from_email, recipient_list)
  File "/home/babugasl/virtualenv/src/3.8/lib/python3.8/site-packages/django/core/mail/__init__.py", line 87, in send_mail
    return mail.send()
  File "/home/babugasl/virtualenv/src/3.8/lib/python3.8/site-packages/django/core/mail/message.py", line 298, in send
    return self.get_connection(fail_silently).send_messages([self])
  File "/home/babugasl/virtualenv/src/3.8/lib/python3.8/site-packages/django/core/mail/backends/smtp.py", line 127, in send_messages
    new_conn_created = self.open()
  File "/home/babugasl/virtualenv/src/3.8/lib/python3.8/site-packages/django/core/mail/backends/smtp.py", line 85, in open
    self.connection = self.connection_class(
  File "/opt/alt/python38/lib64/python3.8/smtplib.py", line 255, in __init__
    (code, msg) = self.connect(host, port)
  File "/opt/alt/python38/lib64/python3.8/smtplib.py", line 339, in connect
    self.sock = self._get_socket(host, port, self.timeout)
  File "/opt/alt/python38/lib64/python3.8/smtplib.py", line 310, in _get_socket
    return socket.create_connection((host, port), timeout,
  File "/opt/alt/python38/lib64/python3.8/socket.py", line 787, in create_connection
    for res in getaddrinfo(host, port, 0, SOCK_STREAM):
  File "/opt/alt/python38/lib64/python3.8/socket.py", line 918, in getaddrinfo
    for res in _socket.getaddrinfo(host, port, family, type, proto, flags):
socket.gaierror: [Errno -2] Name or service not known
Not Found: /ads.txt
Not Found: /static/imgs/text.png
Internal Server Error: /materials/7/flag-issue
Traceback (most recent call last):
  File "/home/babugasl/virtualenv/src/3.8/lib/python3.8/site-packages/django/core/handlers/exception.py", line 55, in inner
    response = get_response(request)
  File "/home/babugasl/virtualenv/src/3.8/lib/python3.8/site-packages/django/core/handlers/base.py", line 197, in _get_response
    response = wrapped_callback(request, *callback_args, **callback_kwargs)
  File "/home/babugasl/src/app/views.py", line 156, in flag_material
    issue.save()
  File "/home/babugasl/virtualenv/src/3.8/lib/python3.8/site-packages/django/db/models/base.py", line 814, in save
    self.save_base(
  File "/home/babugasl/virtualenv/src/3.8/lib/python3.8/site-packages/django/db/models/base.py", line 892, in save_base
    post_save.send(
  File "/home/babugasl/virtualenv/src/3.8/lib/python3.8/site-packages/django/dispatch/dispatcher.py", line 176, in send
    return [
  File "/home/babugasl/virtualenv/src/3.8/lib/python3.8/site-packages/django/dispatch/dispatcher.py", line 177, in <listcomp>
    (receiver, receiver(signal=self, sender=sender, **named))
  File "/home/babugasl/src/user_account/signals.py", line 23, in send_issue_email
    send_mail(subject, message, from_email, recipient_list)
  File "/home/babugasl/virtualenv/src/3.8/lib/python3.8/site-packages/django/core/mail/__init__.py", line 87, in send_mail
    return mail.send()
  File "/home/babugasl/virtualenv/src/3.8/lib/python3.8/site-packages/django/core/mail/message.py", line 298, in send
    return self.get_connection(fail_silently).send_messages([self])
  File "/home/babugasl/virtualenv/src/3.8/lib/python3.8/site-packages/django/core/mail/backends/smtp.py", line 127, in send_messages
    new_conn_created = self.open()
  File "/home/babugasl/virtualenv/src/3.8/lib/python3.8/site-packages/django/core/mail/backends/smtp.py", line 85, in open
    self.connection = self.connection_class(
  File "/opt/alt/python38/lib64/python3.8/smtplib.py", line 255, in __init__
    (code, msg) = self.connect(host, port)
  File "/opt/alt/python38/lib64/python3.8/smtplib.py", line 339, in connect
    self.sock = self._get_socket(host, port, self.timeout)
  File "/opt/alt/python38/lib64/python3.8/smtplib.py", line 310, in _get_socket
    return socket.create_connection((host, port), timeout,
  File "/opt/alt/python38/lib64/python3.8/socket.py", line 787, in create_connection
    for res in getaddrinfo(host, port, 0, SOCK_STREAM):
  File "/opt/alt/python38/lib64/python3.8/socket.py", line 918, in getaddrinfo
    for res in _socket.getaddrinfo(host, port, family, type, proto, flags):
socket.gaierror: [Errno -2] Name or service not known
[UID:4101][3669] Child process with pid: 16142 was killed by signal: 15, core dump: 0
[UID:4101][3669] Child process with pid: 16151 was killed by signal: 15, core dump: 0
Not Found: /favicon.ico
Not Found: /favicon.ico
Not Found: /favicon.ico
Not Found: /favicon.ico
Not Found: /favicon.ico
Not Found: /favicon.ico
Not Found: /favicon.ico
Not Found: /favicon.ico
Not Found: /favicon.ico
Not Found: /favicon.ico
Not Found: /static/imgs/text.png
Not Found: /media/materials/Political-Science/Pols-101/%7B%%20static
Not Found: /favicon.ico
Not Found: /favicon.ico
Not Found: /static/imgs/text.png
Not Found: /static/imgs/text.png
Not Found: /static/imgs/text.png
Not Found: /materials/favicon.ico
Not Found: /site.webmanifest
Not Found: /site.webmanifest
Not Found: /favicon.ico
Not Found: /site.webmanifest
Not Found: /your-website-image-url.jpg
Not Found: /your-website-image-url.jpg
Not Found: /your-website-image-url.jpg
Not Found: /your-website-image-url.jpg
Not Found: /your-website-image-url.jpg
Not Found: /your-website-image-url.jpg
Not Found: /your-website-image-url.jpg
Not Found: /your-website-image-url.jpg
Not Found: /your-website-image-url.jpg
Not Found: /your-website-image-url.jpg
Not Found: /static/imgs/text.png
Not Found: /your-website-image-url.jpg
Not Found: /static/imgs/text.png
Not Found: /favicon.ico
Not Found: /favicon.ico
Not Found: /favicon.ico
Not Found: /favicon.ico
Not Found: /favicon.ico
Not Found: /favicon.ico
Not Found: /favicon.ico
Not Found: /favicon.ico
Not Found: /favicon.ico
Not Found: /robots.txt
Not Found: /sitemap.xml
Not Found: /sitemap.xml
Not Found: /robots.txt
Not Found: /your-website-image-url.jpg
